Workbook

Sheet Cap 3 3.8
A1: PP 41
A2: FIGURA 3.8 PRONÓSTICO DEL CONSUMO NETO DEL SEN 2023-2037, ESCENARIOS DE PLANEACIÓN, ALTO Y BAJO
M4: crecimiento de demanda
M5: comparación con datos prodesen 2022
A24: Escenario de planeación | C24: *Datos en rojo de analisis PRODESEN 2022 | F24: *Datos azul de cuadro 3.4 PRODESEN 2023
A25: Año | B25: Consumo neto (GWh) | C25: Consumo neto (TWh) | L25: *Crecimiento con margen de reserva eficiente y mínimo
A26: 2018 | B26: 317224.49 | C26: =B26/1000 -> 317.22449 | D26: - | E26: * Datos obtenidos de interpolación lineal de https://www.johndcook.com/interpolator.html
A27: 2019 | B27: 324448.98 | C27: =B27/1000 -> 324.44898 | D27: =(C27/C26)-1 -> 0.022774063 | L27: Notamos que el porcentaje de crecimiento de cap instlada esta por arriba de lo previsible, escenario optimista, no dan los tiempos.
A28: 2020 | B28: 316183.67 | C28: =B28/1000 -> 316.18367 | D28: =(C28/C27)-1 -> -0.025474903
A29: 2021 | B29: 327510.2 | C29: =B29/1000 -> 327.5102 | D29: =(C29/C28)-1 -> 0.03582263
A30: 2022 | B30: 333662 | C30: =B30/1000 -> 333.662 | D30: =(C30/C29)-1 -> 0.018783524 | E30: 0.034 | F30: inc
A31: 2023 | B31: ='Cap 3 3.4'!M4 -> 347485 | C31: =B31/1000 -> 347.485 | D31: =(C31/C30)-1 -> 0.041428152
A32: 2024 | B32: ='Cap 3 3.4'!M5 -> 356900 | C32: =B32/1000 -> 356.9 | D32: =(C32/C31)-1 -> 0.027094695
A33: 2025 | B33: ='Cap 3 3.4'!M6 -> 365814 | C33: =B33/1000 -> 365.814 | D33: =(C33/C32)-1 -> 0.024976184
A34: 2026 | B34: ='Cap 3 3.4'!M7 -> 374655 | C34: =B34/1000 -> 374.655 | D34: =(C34/C33)-1 -> 0.02416802
A35: 2027 | B35: ='Cap 3 3.4'!M8 -> 383163 | C35: =B35/1000 -> 383.163 | D35: =(C35/C34)-1 -> 0.022708892
A36: 2028 | B36: ='Cap 3 3.4'!M9 -> 391648 | C36: =B36/1000 -> 391.648 | D36: =(C36/C35)-1 -> 0.022144623 | E36: 391
A37: 2029 | B37: ='Cap 3 3.4'!M10 -> 400178 | C37: =B37/1000 -> 400.178 | D37: =(C37/C36)-1 -> 0.021779761
A38: 2030 | B38: ='Cap 3 3.4'!M11 -> 408822 | C38: =B38/1000 -> 408.822 | D38: =(C38/C37)-1 -> 0.021600388
A39: 2031 | B39: ='Cap 3 3.4'!M12 -> 417618 | C39: =B39/1000 -> 417.618 | D39: =(C39/C38)-1 -> 0.021515476
A40: 2032 | B40: ='Cap 3 3.4'!M13 -> 426986 | C40: =B40/1000 -> 426.986 | D40: =(C40/C39)-1 -> 0.022431983
A41: 2033 | B41: ='Cap 3 3.4'!M14 -> 436761 | C41: =B41/1000 -> 436.761 | D41: =(C41/C40)-1 -> 0.022893022
A42: 2034 | B42: ='Cap 3 3.4'!M15 -> 447063 | C42: =B42/1000 -> 447.063 | D42: =(C42/C41)-1 -> 0.023587271
A43: 2035 | B43: ='Cap 3 3.4'!M16 -> 457603 | C43: =B43/1000 -> 457.603 | D43: =(C43/C42)-1 -> 0.023576096
A44: 2036 | B44: ='Cap 3 3.4'!M17 -> 468693 | C44: =B44/1000 -> 468.693 | D44: =(C44/C43)-1 -> 0.024234981
A45: 2037 | B45: ='Cap 3 3.4'!M18 -> 479987 | C45: =B45/1000 -> 479.987 | D45: =(C45/C44)-1 -> 0.024096797
C46: AVERAGE | D46: =AVERAGE(D27:D45) -> 0.022112719

Sheet Cap 3 3.4
A1: PP 42
A2: CUADRO 3.4 PRONÓSTICO REGIONAL DEL CONSUMO NETO 2023-2037, ESCENARIO DE PLANEACIÓN (GWh)
A3: AÑO/GWH | B3: CENTRAL | C3: ORIENTAL | D3: OCCIDENTAL | E3: NOROESTE | F3: NORTE | G3: NORESTE | H3: PENINSULAR | I3: BAJA CALIFORNIA | J3: BAJA CALIFORNIA SUR | K3: MULEGÉ | L3: SIN | M3: SEN
A4: 2023 | B4: 59871 | C4: 55602 | D4: 74247 | E4: 27143 | F4: 31682 | G4: 63004 | H4: 15397 | I4: 17172 | J4: 3203 | K4: 163 | L4: 326946 | M4: 347485
A5: 2024 | B5: 61048 | C5: 57194 | D5: 76417 | E5: 27796 | F5: 32405 | G5: 64710 | H5: 16040 | I5: 17771 | J5: 3352 | K5: 168 | L5: 335609 | M5: 356900
A6: 2025 | B6: 62196 | C6: 58556 | D6: 78271 | E6: 28546 | F6: 33212 | G6: 66421 | H6: 16684 | I6: 18288 | J6: 3470 | K6: 171 | L6: 343885 | M6: 365814
A7: 2026 | B7: 63438 | C7: 59835 | D7: 80180 | E7: 29183 | F7: 33842 | G7: 68459 | H7: 17160 | I7: 18806 | J7: 3577 | K7: 175 | L7: 352098 | M7: 374655
A8: 2027 | B8: 64611 | C8: 61137 | D8: 82049 | E8: 29758 | F8: 34442 | G8: 70252 | H8: 17702 | I8: 19353 | J8: 3681 | K8: 178 | L8: 359951 | M8: 383163
A9: 2028 | B9: 65801 | C9: 62444 | D9: 84037 | E9: 30365 | F9: 35057 | G9: 71844 | H9: 18254 | I9: 19873 | J9: 3793 | K9: 181 | L9: 367801 | M9: 391648
A10: 2029 | B10: 66964 | C10: 63654 | D10: 86071 | E10: 30992 | F10: 35692 | G10: 73444 | H10: 18855 | I10: 20413 | J10: 3908 | K10: 185 | L10: 375673 | M10: 400178
A11: 2030 | B11: 68117 | C11: 64671 | D11: 88243 | E11: 31624 | F11: 36348 | G11: 75188 | H11: 19472 | I11: 20943 | J11: 4028 | K11: 188 | L11: 383662 | M11: 408822
A12: 2031 | B12: 69265 | C12: 65695 | D12: 90389 | E12: 32259 | F12: 36972 | G12: 77048 | H12: 20130 | I12: 21518 | J12: 4150 | K12: 191 | L12: 391759 | M12: 417618
A13: 2032 | B13: 70453 | C13: 66849 | D13: 92765 | E13: 33011 | F13: 37634 | G13: 78901 | H13: 20808 | I13: 22094 | J13: 4277 | K13: 194 | L13: 400420 | M13: 426986
A14: 2033 | B14: 71608 | C14: 68174 | D14: 95116 | E14: 33751 | F14: 38338 | G14: 80980 | H14: 21489 | I14: 22700 | J14: 4408 | K14: 198 | L14: 409456 | M14: 436761
A15: 2034 | B15: 72849 | C15: 69362 | D15: 97805 | E15: 34499 | F15: 39104 | G15: 83145 | H15: 22208 | I15: 23346 | J15: 4543 | K15: 202 | L15: 418973 | M15: 447063
... A18: 2037 | B18: 76662 | C18: 73283 | D18: 106261 | E18: 36936 | F18: 41446 | G18: 90135 | H18: 24638 | I18: 25429 | J18: 4985 | K18: 212 | L18: 449361 | M18: 479987
B43: AÑO/GWH | C43: 2023 | D43: 2024 | E43: 2025 | F43: 2026 | G43: 2027 | H43: 2028 | I43: 2029 | J43: 2030 | K43: 2031 | L43: 2032 | M43: 2033 | N43: 2034 | O43: 2035 | P43: 2036 | Q43: 2037
B44: OCCIDENTAL | C44: 74247 | D44: 76417 | E44: 78271 | F44: 80180 | G44: 82049 | H44: 84037 | I44: 86071 | J44: 88243 | K44: 90389 | L44: 92765 | M44: 95116 | N44: 97805 | O44: 100482 | P44: 103354 | Q44: 106261
B45: NORESTE | C45: 63004 | D45: 64710 | E45: 66421 | F45: 68459 | G45: 70252 | H45: 71844 | I45: 73444 | J45: 75188 | K45: 77048 | L45: 78901 | M45: 80980 | N45: 83145 | O45: 85393 | P45: 87760 | Q45: 90135
B46: CENTRAL | C46: 59871 | D46: 61048 | E46: 62196 | F46: 63438 | G46: 64611 | H46: 65801 | I46: 66964 | J46: 68117 | K46: 69265 | L46: 70453 | M46: 71608 | N46: 72849 | O46: 74133 | P46: 75410 | Q46: 76662
B47: ORIENTAL | C47: 55602 | D47: 57194 | E47: 58556 | F47: 59835 | G47: 61137 | H47: 62444 | I47: 63654 | J47: 64671 | K47: 65695 | L47: 66849 | M47: 68174 | N47: 69362 | O47: 70597 | P47: 71890 | Q47: 73283
B48: NORTE | C48: 31682 | D48: 32405 | E48: 33212 | F48: 33842 | G48: 34442 | H48: 35057 | I48: 35692 | J48: 36348 | K48: 36972 | L48: 37634 | M48: 38338 | N48: 39104 | O48: 39813 | P48: 40629 | Q48: 41446
B49: NOROESTE | C49: 27143 | D49: 27796 | E49: 28546 | F49: 29183 | G49: 29758 | H49: 30365 | I49: 30992 | J49: 31624 | K49: 32259 | L49: 33011 | M49: 33751 | N49: 34499 | O49: 35273 | P49: 36097 | Q49: 36936
B50: BAJA CALIFORNIA | C50: 17172 | D50: 17771 | E50: 18288 | F50: 18806 | G50: 19353 | H50: 19873 | I50: 20413 | J50: 20943 | K50: 21518 | L50: 22094 | M50: 22700 | N50: 23346 | O50: 24015 | P50: 24703 | Q50: 25429
B51: PENINSULAR | C51: 15397 | D51: 16040 | E51: 16684 | F51: 17160 | G51: 17702 | H51: 18254 | I51: 18855 | J51: 19472 | K51: 20130 | L51: 20808 | M51: 21489 | N51: 22208 | O51: 23004 | P51: 23809 | Q51: 24638
B52: BAJA CALIFORNIA SUR | C52: 3203 | D52: 3352 | E52: 3470 | F52: 3577 | G52: 3681 | H52: 3793 | I52: 3908 | J52: 4028 | K52: 4150 | L52: 4277 | M52: 4408 | N52: 4543 | O52: 4687 | P52: 4833 | Q52: 4985
B53: MULEGÉ | C53: 163 | D53: 168 | E53: 171 | F53: 175 | G53: 178 | H53: 181 | I53: 185 | J53: 188 | K53: 191 | L53: 194 | M53: 198 | N53: 202 | O53: 205 | P53: 208 | Q53: 212
B58: AÑO/GWH | C58: 2023 | D58: 2024
B59: OCCIDENTAL | C59: 74247 | D59: 76417

Sheet Cap 4 4.2
A1: PP 54
A2: FIGURA 4.2 EVOLUCIÓN ESPERADA DE LA CAPACIDAD INSTALADA ACUMULADA 2023–2037 (MW)
B22: Escenario PRODESEN | E22: Escenario ENEL
A23: Año | B23: MW 4.2 | C23: ESTIMADO 4.3
A24: 2022 | B24: 93005.464 | C24: 92504 | D24: =C24-B24 -> -501.46448 | E24: * Datos obtenidos de interpolación lineal de https://www.johndcook.com/interpolator.html
A25: 2023 | B25: 95191.257 | C25: 95514.397 | D25: =C25-B25 -> 323.14028
A26: 2024 | B26: 100109.29 | C26: 101637.59 | D26: =C26-B26 -> 1528.3036
A27: 2025 | B27: 108579.23 | C27: 108568.54 | D27: =C27-B27 -> -10.69982
A28: 2026 | B28: 112131.15 | C28: 107461.13 | D28: =C28-B28 -> -4670.0136
A29: 2027 | B29: 116775.96 | C29: 117401.18 | D29: =C29-B29 -> 625.22162
A30: 2028 | B30: 121967.21 | C30: 122655.7 | D30: =C30-B30 -> 688.49181
A31: 2029 | B31: 127158.47 | C31: 125378 | D31: =C31-B31 -> -1780.4669
A32: 2030 | B32: 133989.07 | C32: 134043.15 | D32: =C32-B32 -> 54.080757
A33: 2031 | B33: 138633.88 | C33: 139083.57 | D33: =C33-B33 -> 449.68582
A34: 2032 | B34: 143278.69 | C34: 143150.18 | D34: =C34-B34 -> -128.5115
A35: 2033 | B35: 145191.26 | C35: 146238.83 | D35: =C35-B35 -> 1047.5704
A36: 2034 | B36: 148196.72 | C36: 151635 | D36: =C36-B36 -> 3438.2808
... A39: 2037 | B39: 157213.11 | C39: 128243.37 | D39: =C39-B39 -> -28969.749
A40: 2038 | B40: 165894.81
A41: 2039 | B41: 170375.68
A42: 2040 | B42: 174856.56
A43: 2041 | B43: 179337.43
A44: 2042 | B44: 183818.31
A45: 2043 | B45: 188299.18
A46: 2044 | B46: 192780.05
A47: 2045 | B47: 197260.93

Sheet Cap 4 4.3, 4.5, 4.6, 4.7
A1: PP 55
A2: FIGURA 4.3 EVOLUCIÓN ESPERADA DE LA CAPACIDAD INSTALADA ACUMULADA POR TECNOLOGÍA, 2023–2037 (MW) | L2: Ciclo Combinado
L3: Combustion Interna
L4: Cog Eficiente
L5: Baterías
L6: Termica convencional
L7: Fotovoltaica
L8: Nucleoelectrica
L9: GD-FV
L10: Carboelectrica
L11: Hidroelectrica
L12: Geotermoelectrica
L13: CC Hidrogeno
L14: Turbogas
... L20: * Datos obtenidos de interpolación lineal de https://www.johndcook.com/interpolator.html
A22: Año | B22: Ciclo Combinado | C22: =L6 -> Termica convencional | D22: =L10 -> Carboelectrica | E22: =L14 -> Turbogas | F22: =L3 -> Combustion Interna | G22: Fotovoltaico | H22: Hidroelectrico | I22: Eoleoelectrica | J22: Cogeneracion eficiente | K22: Nucleoelectrica | L22: Geotermoelectrica | M22: Bioenergia | N22: Baterias | O22: GD-FV | P22: CCH2
A23: 2022 | B23: 34733.728 | C23: 45384.615
A24: 2023 | B24: 34142.012
A25: 2024
A26: 2025
A27: 2026
A28: 2027
A29: 2028
A30: 2029
A31: 2030
A32: 2031
A33: 2032
A34: 2033
A35: 2034
A36: 2035
... A38: 2037
B39: 1 | C39: 2 | D39: 3 | E39: 4 | F39: 5 | G39: 6 | H39: 7 | I39: 8 | J39: 9 | K39: 10 | L39: 11 | M39: 12 | N39: 13 | O39: 14 | P39: 15 | Q39: 16
B40: 2022 | C40: 2023 | D40: 2024 | E40: 2025 | F40: 2026 | G40: 2027 | H40: 2028 | I40: 2029 | J40: 2030 | K40: 2031 | L40: 2032 | M40: 2033 | N40: 2034 | O40: 2035 | P40: 2036 | Q40: 2037
A41: Ciclo Combinado | B41: 34620.902 | C41: 34620.902 | D41: 37011.612 | E41: 41195.355 | F41: 41195.355 | G41: 41195.355 | H41: 41195.355 | I41: 41195.355 | J41: 42988.388 | K41: 44781.421 | L41: 46574.454 | M41: 46574.454 | N41: 46574.454 | O41: 45976.776 | P41: 45379.098 | Q41: 45976.776
A42: Termica convencional | B42: 45976.776 | C42: 45976.776 | D42: 45976.776 | E42: 49562.842 | F42: 49562.842 | G42: 49562.842 | H42: 49562.842 | I42: 49562.842 | J42: 51355.874 | K42: 54344.262 | L42: 55539.617 | M42: 55539.617 | N42: 55539.617 | O42: 53746.585 | P42: 53746.585 | Q42: 53746.585
A43: Carboelectrica | B43: 51355.874 | C43: 51355.874 | D43: 52551.23 | E43: 54941.94 | F43: 54941.94 | G43: 54941.94 | H43: 54941.94 | I43: 54941.94 | J43: 57332.65 | K43: 59125.683 | L43: 60918.716 | M43: 60918.716 | N43: 60918.716 | O43: 60918.716 | P43: 60918.716 | Q43: 60918.716
A44: Turbogas | B44: 54852.071 | C44: 54852.071 | D44: 55443.787 | E44: 58994.083 | F44: 58994.083 | G44: 58994.083 | H44: 58994.083 | I44: 58994.083 | J44: 62114.071 | K44: 63313.462 | L44: 64476.452 | M44: 64476.452 | N44: 64476.452 | O44: 63309.426 | P44: 63309.426 | Q44: 63309.426
A45: Combustion Interna | B45: 56137.295 | C45: 56137.295 | D45: 56734.973 | E45: 60321.038 | F45: 60321.038 | G45: 60321.038 | H45: 60321.038 | I45: 60321.038 | J45: 63309.426 | K45: 65106.806 | L45: 66267.412 | M45: 66267.412 | N45: 66267.412 | O45: 65102.459 | P45: 65102.459 | Q45: 65700.137
A46: Fotovoltaico | B46: 62711.749 | C46: 63907.104 | D46: 66895.492 | E46: 72872.268 | F46: 75262.978 | G46: 77056.011 | H46: 80044.399 | I46: 81239.754 | J46: 84228.142 | K46: 89009.563 | L46: 91400.273 | M46: 91699.112 | N46: 92595.628 | O46: 93193.306 | P46: 94986.339 | Q46: 97377.049
A47: Hidroelectrico | B47: 75262.978 | C47: 77056.011 | D47: 80642.077 | E47: 86618.852 | F47: 89009.563 | G47: 90802.596 | H47: 93790.984 | I47: 96181.694 | J47: 100963.11 | K47: 104549.18 | L47: 106939.89 | M47: 106939.89 | N47: 110525.96 | O47: 110525.96 | P47: 111721.31 | Q47: 114112.02
...

Sheet Factor de ajuste
A1: TECNOLOGIA | B1: 2022 | C1: 2026 | D1: 2030 | E1: 2037 | F1: Funciones | G1: 2022 | H1: 2030 | I1: 2037
A2: Ciclo Combinado | B2: 34733.728 | C2: 41839.216 | D2: 40000 | E2: 42000 | F2: "-1633.1*()^2+10166()+26201 | G2: 34733.728 | H2: 40000 | I2: 42000 | J2: 0.373459 | K2: Escenario más aproximado
A3: Termica convencional | B3: 45384.615 | C3: 48343.195 | D3: 50000 | E3: 54000 | F3: "-307.69*()^2+5538.5()+4015 | G3: 10650.888 | H3: 10000 | I3: 12000 | J3: 0.11451894
A4: Carboelectrica | B4: 51301.775 | C4: 53668.639 | D4: 55100 | E4: 60000 | F4: "550.89*()^2+2145.6()+48605 | G4: 5917.1598 | H4: 5100 | I4: 6000 | J4: 0.063621636
A5: Turbogas | B5: 54852.071 | C5: 55045.65 | D5: 60000 | E5: 62000 | F5: "-1574*()^2+9869.8()+46555" | G5: 3550.2959 | H5: 4900 | I5: 2000 | J5: 0.038172981
A6: Combustion Interna | B6: 56035.503 | C6: 57146.874 | D6: 61000 | E6: 64500 | F6: "52483*e^0.0703*() | G6: 1183.432 | H6: 1000 | I6: 2500 | J6: 0.012724327
A7: Fotovoltaico | B7: 62544.379 | C7: 69508.668 | D7: 85000 | E7: 96000 | F7: "-5727.8*()^2+39639*()+28633" | G7: 6508.8757 | H7: 24000 | I7: 31500 | J7: 0.069983799
A8: Hidroelectrico | B8: 76153.846 | C8: 76670.816 | D8: 101000 | E8: 102500 | F8: "-11672*()^2+59865*()+27962" | G8: 13609.467 | H8: 16000 | I8: 6500 | J8: 0.14632976
A9: Eoleoelectrica | B9: 83846.154 | C9: 86032.458 | D9: 113000 | E9: 125000 | F9: "-8576.9*()^2+54885*()+37538" | G9: 7692.3077 | H9: 12000 | I9: 22500 | J9: 0.082708126
A10: Cogeneracion eficiente | B10: 86213.018 | C10: 87000 | D10: 115000 | E10: 128000 | F10: "-7893.5*()^2+52467*()+41639" | G10: 2366.8639 | H10: 2000 | I10: 3000 | J10: 0.025448654
A11: Nucleoelectrica | B11: 88579.882 | C11: 89000 | D11: 118000 | E11: 130000 | F11: "-8710.1*()^2+55550*()+41740" | G11: 2366.8639 | H11: 3000 | I11: 2000 | J11: 0.025448654
A12: Geotermoelectrica | B12: 90355.03 | C12: 91000 | D12: 119000 | E12: 130100 | F12: "-8772.5*()^2+54962*()+44165" | G12: 1775.1479 | H12: 1000 | I12: 100 | J12: 0.019086491
A13: Bioenergia | B13: 90946.746 | C13: 92000 | D13: 120000 | E13: 130300 | F13: "-9376.6*()^2+57183*()+43140" | G13: 591.71598 | H13: 1000 | I13: 200 | J13: 0.0063621636
A14: Baterias | B14: 90946.746 | C14: 93552.091 | D14: 124000 | E14: 139000 | F14: "-9026.6*()^2+60133*()+39840" | G14: 0 | H14: 4000 | I14: 8700 | J14: 0
... A16: CCH2 | B16: 93005.464 | C16: 112131.15 | D16: 138633.88 | E16: 157213.11 | F16: "-13525*()^2+86202*()+20328" | G16: 0 | H16: 0 | I16: 3144.2623 | J16: 0
B17: 1097904.4 | C17: 1165069.9 | D17: 1438367.8 | E17: 1574682 | F17: 0 | G17: 93005.464 | H17: 138633.88
B21: 2022 | C21: Factor
B22: 34733.728 | C22: =B22/$B$37 -> 0.373459 | D22: =C22*'Cap 4 4.2'!$B$24 -> 34733.728
B23: 10650.888 | C23: =B23/$B$37 -> 0.11451894 | D23: =C23*'Cap 4 4.2'!$B$24 -> 10650.888
B24: 5917.1598 | C24: =B24/$B$37 -> 0.063621636 | D24: =C24*'Cap 4 4.2'!$B$24 -> 5917.1598
B25: 3550.2959 | C25: =B25/$B$37 -> 0.038172981 | D25: =C25*'Cap 4 4.2'!$B$24 -> 3550.2959
B26: 1183.432 | C26: =B26/$B$37 -> 0.012724327 | D26: =C26*'Cap 4 4.2'!$B$24 -> 1183.432
B27: 6508.8757 | C27: =B27/$B$37 -> 0.069983799 | D27: =C27*'Cap 4 4.2'!$B$24 -> 6508.8757
B28: 13609.467 | C28: =B28/$B$37 -> 0.14632976 | D28: =C28*'Cap 4 4.2'!$B$24 -> 13609.467
B29: 7692.3077 | C29: =B29/$B$37 -> 0.082708126 | D29: =C29*'Cap 4 4.2'!$B$24 -> 7692.3077
B30: 2366.8639 | C30: =B30/$B$37 -> 0.025448654 | D30: =C30*'Cap 4 4.2'!$B$24 -> 2366.8639
B31: 2366.8639 | C31: =B31/$B$37 -> 0.025448654 | D31: =C31*'Cap 4 4.2'!$B$24 -> 2366.8639
B32: 1775.1479 | C32: =B32/$B$37 -> 0.019086491 | D32: =C32*'Cap 4 4.2'!$B$24 -> 1775.1479
B33: 591.71598 | C33: =B33/$B$37 -> 0.0063621636 | D33: =C33*'Cap 4 4.2'!$B$24 -> 591.71598
... B36: 0 | C36: =B36/$B$37 -> 0 | D36: =C36*'Cap 4 4.2'!$B$24 -> 0
B37: =SUM(B22:B36) -> 93005.464 | C37: =SUM(C22:C36) -> 1 | D37: =SUM(D22:D36) -> 93005.464

Sheet Data 4.3
A1: Datos interpolados con balance final de figura 4.2, capacidad instalada ACUMULADA 30% de error
B2: 2022 | C2: 2023 | D2: 2024 | E2: 2025 | F2: 2026 | G2: 2027 | H2: 2028 | I2: 2029 | J2: 2030 | K2: 2031 | L2: 2032 | M2: 2033 | N2: 2034 | O2: 2035 | P2: 2036 | Q2: 2037
A3: Ciclo Combinado | B3: 34620.902 | C3: 34620.902 | D3: 37011.612 | E3: 41195.355 | F3: 41195.355 | G3: 41195.355 | H3: 41195.355 | I3: 41195.355 | J3: 42988.388 | K3: 44781.421 | L3: 46574.454 | M3: 46574.454 | N3: 46574.454 | O3: 45976.776 | P3: 45379.098 | Q3: 45976.776
A4: Termica convencional | B4: 45976.776 | C4: 45976.776 | D4: 45976.776 | E4: 49562.842 | F4: 49562.842 | G4: 49562.842 | H4: 49562.842 | I4: 49562.842 | J4: 51355.874 | K4: 54344.262 | L4: 55539.617 | M4: 55539.617 | N4: 55539.617 | O4: 53746.585 | P4: 53746.585 | Q4: 53746.585
A5: Carboelectrica | B5: 51355.874 | C5: 51355.874 | D5: 51355.874 | E5: 54941.94 | F5: 54941.94 | G5: 54941.94 | H5: 54941.94 | I5: 54941.94 | J5: 57332.65 | K5: 59125.683 | L5: 60918.716 | M5: 60918.716 | N5: 60918.716 | O5: 60918.716 | P5: 60918.716 | Q5: 60918.716
A6: Turbogas | B6: 54852.071 | C6: 54852.071 | D6: 55443.787 | E6: 58994.083 | F6: 58994.083 | G6: 58994.083 | H6: 58994.083 | I6: 58994.083 | J6: 62114.071 | K6: 63313.462 | L6: 64476.452 | M6: 64476.452 | N6: 64476.452 | O6: 63309.426 | P6: 63309.426 | Q6: 63309.426
A7: Combustion Interna | B7: 56137.295 | C7: 56137.295 | D7: 56734.973 | E7: 60321.038 | F7: 60321.038 | G7: 60321.038 | H7: 60321.038 | I7: 60321.038 | J7: 63309.426 | K7: 65106.806 | L7: 66267.412 | M7: 66267.412 | N7: 66267.412 | O7: 65102.459 | P7: 65102.459 | Q7: 65700.137
A8: Fotovoltaico | B8: 62711.749 | C8: 63907.104 | D8: 66895.492 | E8: 72872.268 | F8: 75262.978 | G8: 77056.011 | H8: 80044.399 | I8: 81239.754 | J8: 84228.142 | K8: 89009.563 | L8: 91400.273 | M8: 91699.112 | N8: 92595.628 | O8: 93193.306 | P8: 94986.339 | Q8: 97377.049
A9: Hidroelectrico | B9: 75262.978 | C9: 77056.011 | D9: 80642.077 | E9: 86618.852 | F9: 89009.563 | G9: 90802.596 | H9: 93790.984 | I9: 96181.694 | J9: 100963.11 | K9: 104549.18 | L9: 106939.89 | M9: 106939.89 | N9: 110525.96 | O9: 110525.96 | P9: 111721.31 | Q9: 114112.02
A10: Eoleoelectrica | B10: 83032.787 | C10: 85423.497 | D10: 89607.24 | E10: 96181.694 | F10: 100365.44 | G10: 103353.83 | H10: 106342.21 | I10: 109000.46 | J10: 113000 | K10: 117711.54 | L10: 120593.2 | M10: 121881.83 | N10: 123077.19 | O10: 123674.86 | P10: 124870.22 | Q10: 127260.93
A11: Cogeneracion eficiente | B11: 86213.018 | C11: 87988.166 | D11: 91538.462 | E11: 98034.188 | F11: 102814.81 | G11: 105777.78 | H11: 108740.74 | I11: 113842.59 | J11: 115000 | K11: 121298.23 | L11: 124772.1 | M11: 125467.9 | N11: 126663.25 | O11: 127260.93 | P11: 128456.28 | Q11: 131444.67
A12: Nucleoelectrica | B12: 88579.882 | C12: 89763.314 | D12: 92721.893 | E12: 100427.35 | F12: 104000 | G12: 106962.96 | H12: 109925.93 | I12: 115053.13 | J12: 118000 | K12: 122493.79 | L12: 125966.08 | M12: 126663.25 | N12: 127858.61 | O12: 128456.28 | P12: 129651.64 | Q12: 132640.03
A13: Geotermoelectrica | B13: 90946.746 | C13: 90946.746 | D13: 95088.757 | E13: 101623.93 | F13: 104592.59 | G13: 108148.15 | H13: 111703.7 | I13: 116263.66 | J13: 119000 | K13: 123689.35 | L13: 127160.05 | M13: 127858.61 | N13: 129053.96 | O13: 129651.64 | P13: 130846.99 | Q13: 133835.38
A14: Bioenergia | B14: 90946.746 | C14: 90946.746 | D14: 95088.757 | E14: 103418.8 | F14: 105185.19 | G14: 108740.74 | H14: 112296.3 | I14: 116868.93 | J14: 120000 | K14: 124287.13 | L14: 127757.04 | M14: 128456.28 | N14: 129651.64 | O14: 130249.32 | P14: 131444.67 | Q14: 134433.06
... A18: SUMA CALIBRADA | B18: 93005.464 | C18: 95191.257 | D18: 100109.29 | E18: 108579.23 | F18: 112131.15 | G18: 116775.96 | H18: 121967.21 | I18: 127158.47 | J18: 133989.07 | K18: 138633.88 | L18: 143278.69 | M18: 145191.26 | N18: 148196.72 | O18: 150109.29 | P18: 153387.98 | Q18: 157213.11
A20: Datos nominales (no acumulados) con balance 4.2 30% de error
B21: 2022 | C21: 2023 | D21: 2024 | E21: 2025 | F21: 2026 | G21: 2027 | H21: 2028 | I21: 2029 | J21: 2030 | K21: 2031 | L21: 2032 | M21: 2033 | N21: 2034 | O21: 2035 | P21: 2036 | Q21: 2037
A22: Ciclo Combinado | B22: 34413 | C22: =C3 -> 34620.902 | D22: =D3 -> 37011.612 | E22: =E3 -> 41195.355 | F22: 41518.49 | G22: =G3 -> 41195.355 | H22: =H3 -> 41195.355 | I22: =I3 -> 41195.355 | J22: =J3 -> 42988.388 | K22: =K3 -> 44781.421 | L22: =L3 -> 46574.454 | M22: =M3 -> 46574.454 | N22: =N3 -> 46574.454 | ... Q22: =Q3 -> 45976.776
A23: Termica convencional | B23: 12211 | C23: =C4-C3 -> 11355.874 | D23: =D4-D3 -> 8965.1639 | E23: =E4-E3 -> 8367.4863 | F23: 12211 | G23: =G4-G3 -> 8367.4863 | H23: =H4-H3 -> 8367.4863 | I23: =I4-I3 -> 8367.4863 | J23: =J4-J3 -> 8367.4863 | K23: =K4-K3 -> 9562.8415 | L23: =L4-L3 -> 8965.1639 | M23: =M4-M3 -> 8965.1639 | N23: =N4-N3 -> 8965.1639 | ... Q23: =Q4-Q3 -> 7769.8087
A24: Carboelectrica | B24: 5463 | C24: =C5-C4 -> 5379.0984 | D24: =D5-D4 -> 5379.0984 | E24: =E5-E4 -> 5379.0984 | F24: 5463 | G24: =G5-G4 -> 5379.0984 | H24: =H5-H4 -> 5379.0984 | I24: =I5-I4 -> 5379.0984 | J24: =J5-J4 -> 5976.776 | K24: =K5-K4 -> 4781.4208 | L24: =L5-L4 -> 5379.0984 | M24: =M5-M4 -> 5379.0984 | N24: =N5-N4 -> 5379.0984 | ... Q24: =Q5-Q4 -> 7172.1311
A25: Turbogas | B25: 4404 | C25: =C6-C5 -> 3496.1967 | D25: =D6-D5 -> 4087.9127 | E25: =E6-E5 -> 4052.1429 | F25: 4404 | G25: =G6-G5 -> 4052.1429 | H25: =H6-H5 -> 4052.1429 | I25: =I6-I5 -> 4052.1429 | J25: =J6-J5 -> 4781.4208 | K25: =K6-K5 -> 4187.7794 | L25: =L6-L5 -> 3557.7363 | M25: =M6-M5 -> 3557.7363 | N25: =N6-N5 -> 3557.7363 | ... Q25: =Q6-Q5 -> 2390.7104
A26: Combustion Interna | B26: 850 | C26: =C7-C6 -> 1285.2241 | D26: =D7-D6 -> 1291.1857 | E26: =E7-E6 -> 1326.9554 | F26: 1839.37 | G26: =G7-G6 -> 1326.9554 | H26: =H7-H6 -> 1326.9554 | I26: =I7-I6 -> 1326.9554 | J26: =J7-J6 -> 1195.3552 | K26: =K7-K6 -> 1793.3433 | L26: =L7-L6 -> 1790.9599 | M26: =M7-M6 -> 1790.9599 | N26: =N7-N6 -> 1790.9599 | ... Q26: =Q7-Q6 -> 2390.7104
A27: Fotovoltaico | B27: 7906.44 | C27: =C8-C7 -> 7769.8087 | D27: =D8-D7 -> 10160.519 | E27: =E8-E7 -> 12551.23 | F27: 13479.29 | G27: =G8-G7 -> 16734.973 | H27: =H8-H7 -> 19723.361 | I27: =I8-I7 -> 20918.716 | J27: =J8-J7 -> 20918.716 | K27: =K8-K7 -> 23902.757 | L27: =L8-L7 -> 25132.861 | M27: =M8-M7 -> 25431.7 | N27: =N8-N7 -> 26328.216 | ... Q27: =Q8-Q7 -> 31676.913
A28: Hidroelectrico | B28: 12661 | C28: =C9-C8 -> 13148.907 | D28: =D9-D8 -> 13746.585 | E28: =E9-E8 -> 13746.585 | F28: 13746.58 | G28: =G9-G8 -> 13746.585 | H28: =H9-H8 -> 13746.585 | I28: =I9-I8 -> 14941.94 | J28: =J9-J8 -> 16734.973 | K28: =K9-K8 -> 15539.617 | L28: =L9-L8 -> 15539.617 | M28: =M9-M8 -> 15240.779 | N28: =N9-N8 -> 17930.328 | ... Q28: =Q9-Q8 -> 16734.973
A29: Eoleoelectrica | B29: 8278.2 | C29: =C10-C9 -> 8367.4863 | D29: =D10-D9 -> 8965.1639 | E29: =E10-E9 -> 9562.8415 | F29: 9107.3 | G29: =G10-G9 -> 12551.23 | H29: =H10-H9 -> 12551.23 | I29: =I10-I9 -> 12818.761 | J29: =J10-J9 -> 12036.885 | K29: =K10-K9 -> 13162.361 | L29: =L10-L9 -> 13653.306 | M29: =M10-M9 -> 14941.94 | N29: =N10-N9 -> 12551.23 | ... Q29: =Q10-Q9 -> 13148.907
A30: Cogeneracion eficiente | B30: 2308 | C30: =C11-C10 -> 2564.6684 | D30: =D11-D10 -> 1931.2211 | E30: =E11-E10 -> 1852.494 | F30: 2626.96 | G30: =G11-G10 -> 2423.9526 | H30: =H11-H10 -> 2398.5276 | I30: =I11-I10 -> 4842.1372 | J30: =J11-J10 -> 2000 | K30: =K11-K10 -> 3586.6865 | L30: =L11-L10 -> 4178.9065 | M30: =M11-M10 -> 3586.0656 | N30: =N11-N10 -> 3586.0656 | ... Q30: =Q11-Q10 -> 4183.7432
A31: Nucleoelectrica | B31: 1608 | C31: =C12-C11 -> 1775.1479 | D31: =D12-D11 -> 1183.432 | E31: =E12-E11 -> 2393.1624 | F31: 1608 | G31: =G12-G11 -> 1185.1852 | H31: =H12-H11 -> 1185.1852 | I31: =I12-I11 -> 1210.5343 | J31: =J12-J11 -> 3000 | K31: =K12-K11 -> 1195.5622 | L31: =L12-L11 -> 1193.9733 | M31: =M12-M11 -> 1195.3552 | N31: =N12-N11 -> 1195.3552 | ... Q31: =Q12-Q11 -> 1195.3552
A32: Geotermoelectrica | B32: 976 | C32: =C13-C12 -> 1183.432 | D32: =D13-D12 -> 2366.8639 | E32: =E13-E12 -> 1196.5812 | F32: 1196.58 | G32: =G13-G12 -> 1185.1852 | H32: =H13-H12 -> 1777.7778 | I32: =I13-I12 -> 1210.5343 | J32: =J13-J12 -> 1000 | K32: =K13-K12 -> 1195.5622 | L32: =L13-L12 -> 1193.9733 | M32: =M13-M12 -> 1195.3552 | N32: =N13-N12 -> 1195.3552 | ... Q32: =Q13-Q12 -> 1195.3552
A33: Bioenergia | B33: 505 | C33: =C14-C13 -> 0 | D33: =D14-D13 -> 0 | E33: =E14-E13 -> 1794.8718 | F33: 592.59 | G33: =G14-G13 -> 592.59259 | H33: =H14-H13 -> 592.59259 | I33: =I14-I13 -> 605.26715 | J33: =J14-J13 -> 1000 | K33: =K14-K13 -> 597.78109 | L33: =L14-L13 -> 596.98664 | M33: =M14-M13 -> 597.6776 | N33: =N14-N13 -> 597.6776 | ... Q33: =Q14-Q13 -> 597.6776
A34: Baterias | B34: 20 | C34: =C15-C14 -> 0 | D34: =D15-D14 -> 1183.432 | E34: =E15-E14 -> 598.2906 | F34: 2625.35 | G34: =G15-G14 -> 2370.3704 | H34: =H15-H14 -> 2370.3704 | I34: =I15-I14 -> 4236.8701 | J34: =J15-J14 -> 4000 | K34: =K15-K14 -> 5977.8109 | L34: =L15-L14 -> 5969.8664 | M34: =M15-M14 -> 5976.776 | N34: =N15-N14 -> 7172.1311 | ... Q34: =Q15-Q14 -> 8367.4863
A35: GD-FV | B35: 2613 | C35: =C16-C15 -> 4244.5113 | D35: =D16-D15 -> 3837.1003 | E35: =E16-E15 -> 4562.141 | F35: 4703.65 | G35: =G16-G15 -> 5664.8452 | H35: =H16-H15 -> 7300.5464 | I35: =I16-I15 -> 6052.6715 | J35: =J16-J15 -> 9989.071 | K35: =K16-K15 -> 8368.9353 | L35: =L16-L15 -> 9551.7862 | M35: =M16-M15 -> 9562.8415 | N35: =N16-N15 -> 10160.519 | ... Q35: =Q16-Q15 -> 11355.874 | S35: Convencional | T35: RES | U35: TOTAL | Y35: Convencional | Z35: RES | AA35: TOTAL
A36: CCH2 | B36: =B17-B16 -> 0 | C36: =C17-C16 -> 0 | D36: =D17-D16 -> 0 | E36: =E17-E16 -> 0 | F36: =F17-F16 -> 0 | G36: =G17-G16 -> 0 | H36: =H17-H16 -> 0 | I36: =I17-I16 -> 0 | ... Q36: =Q17-Q16 -> 3056.694 | S36: =SUM(B22:B26,B30,) -> 59649 | T36: =SUM(B27:B29,B31:B35) -> 34567.64 | U36: =SUM(S36:T36) -> 94216.64 | Y36: =SUM(F22:F26,F30,F34) -> 70688.17 | Z36: =SUM(F27:F29,F31:F33,F35) -> 44433.99 | AA36: =SUM(Y36:Z36) -> 115122.16
A37: SUMA CALIBRADA | B37: =SUM(B22:B36) -> 94216.64 | C37: =SUM(C22:C36) -> 95191.257 | D37: =SUM(D22:D36) -> 100109.29 | E37: =SUM(E22:E36) -> 108579.23 | F37: =SUM(F22:F36) -> 115122.16 | G37: =SUM(G22:G36) -> 116775.96 | H37: =SUM(H22:H36) -> 121967.21 | I37: =SUM(I22:I36) -> 127158.47 | ... Q37: =SUM(Q22:Q36) -> 157213.11 | S37: =S36/U36 -> 0.63310473 | T37: =T36/U36 -> 0.36689527 | Y37: =Y36/AA36 -> 0.61402748 | Z37: =Z36/AA36 -> 0.38597252
A39: Datos ajustados 20% de error | D39: *Valores en rojo representan valores ajustados con datos PRODESEN, Yr 2022, 2026 y 2037 años de calibración
B40: 2022 | C40: 2023 | D40: 2024 | E40: 2025 | F40: 2026 | G40: 2027 | H40: 2028 | I40: 2029 | J40: 2030 | K40: 2031 | L40: 2032 | M40: 2033 | N40: 2034 | O40: 2035 | P40: 2036 | Q40: 2037
A41: Ciclo Combinado | B41: 34413 | C41: =SUM(J152) -> 34620.9 | D41: 37011.612 | E41: 41195.355 | F41: =M151+M152 -> 41518.49 | G41: 41195.355 | H41: 41195.355 | I41: 41195.355 | J41: 42988.388 | K41: 44781.421 | L41: 46574.454 | M41: 46574.454 | N41: 46574.454 | O41: 45976.776 | P41: 45379.098 | Q41: =F41+F41*'Cap 4 4.3, 4.5, 4.6, 4.7'!B110 -> 47027.994
A42: Termica convencional | B42: =I164+I163 -> 12211 | C42: =J164+J163 -> 12211 | D42: 8965.1639 | E42: 8367.4863 | F42: =SUM(M163:M164) -> 12211 | G42: 8367.4863 | H42: 8367.4863 | I42: 8367.4863 | J42: 8367.4863 | K42: 9562.8415 | L42: 8965.1639 | M42: 8965.1639 | N42: 8965.1639 | O42: 7769.8087 | P42: 8367.4863 | Q42: 7769.8087
A43: Carboelectrica | B43: 5463 | C43: =J150 -> 5463 | D43: 5379.0984 | E43: 5379.0984 | F43: =M150 -> 5463 | G43: 5379.0984 | H43: 5379.0984 | I43: 5379.0984 | J43: 5976.776 | K43: 4781.4208 | L43: 5379.0984 | M43: 5379.0984 | N43: 5379.0984 | O43: 7172.1311 | P43: 7172.1311 | Q43: 7172.1311
A44: Turbogas | B44: =I165+I169 -> 4404 | C44: =J165+J169 -> 4404 | D44: 4087.9127 | E44: 4052.1429 | F44: =M169+M165 -> 4404 | G44: 4052.1429 | H44: 4052.1429 | I44: 4052.1429 | J44: 4781.4208 | K44: 4187.7794 | L44: 3557.7363 | M44: 3557.7363 | N44: 3557.7363 | O44: 2390.7104 | P44: 2390.7104 | Q44: 2390.7104
A45: Combustion Interna | B45: =SUM(I154:I156) -> 850 | C45: =SUM(J154:J156) -> 1178.37 | D45: 1291.1857 | E45: 1326.9554 | F45: =SUM(M154:M156) -> 1839.37 | G45: 1326.9554 | H45: 1326.9554 | I45: 1326.9554 | J45: 1195.3552 | K45: 1793.3433 | L45: 1790.9599 | M45: 1790.9599 | N45: 1790.9599 | O45: 1793.0328 | P45: 1793.0328 | Q45: =F45+F45*'Cap 4 4.3, 4.5, 4.6, 4.7'!B111 -> 1840.1057
...

Sheet Cap 4 4.10
A1: PP 60
A2: FIGURA 4.10 AVANCE EN EL CUMPLIMIENTO DE LOS COMPROMISOS DE MÉXICO EN LA GENERACIÓN DE ELECTRICIDAD CON ENERGÍAS LIMPIAS 2018-2022
B27: Año | C27: % EL | D27: % Meta LTE | E27: Estimación
A28: 1 | B28: 2018 | C28: 0.225 | D28: 0.25 | E28: =0.0167*(A28)+0.2333 -> 0.25 | F28: =E28 -> 0.25
A29: 2 | B29: 2019 | C29: 0.222 | E29: =0.0167*(A29)+0.2333 -> 0.2667 | F29: =E29-E28 -> 0.0167
A30: 3 | B30: 2020 | C30: 0.266 | E30: =0.0167*(A30)+0.2333 -> 0.2834 | F30: =E30-E29 -> 0.0167
A31: 4 | B31: 2021 | C31: 0.295 | D31: 0.3 | E31: =0.0167*(A31)+0.2333 -> 0.3001 | F31: =E31-E30 -> 0.0167
A32: 5 | B32: 2022 | C32: 0.312 | E32: =0.0167*(A32)+0.2333 -> 0.3168 | F32: =E32-E31 -> 0.0167
A33: 6 | B33: 2023 | C33: 0.3381 | E33: =0.0167*(A33)+0.2333 -> 0.3335 | F33: =E33-E32 -> 0.0167
A34: 7 | B34: 2024 | C34: 0.3628 | E34: =0.0167*(A34)+0.2333 -> 0.3502 | F34: =E34-E33 -> 0.0167
A35: 8 | B35: 2025 | C35: 0.3875 | E35: =0.0167*(A35)+0.2333 -> 0.3669 | F35: =E35-E34 -> 0.0167
A36: 9 | B36: 2026 | C36: 0.4122 | E36: =0.0167*(A36)+0.2333 -> 0.3836 | F36: =E36-E35 -> 0.0167
A37: 10 | B37: 2027 | C37: 0.4369 | E37: =0.0167*(A37)+0.2333 -> 0.4003 | F37: =E37-E36 -> 0.0167
A38: 11 | B38: 2028 | C38: 0.4616 | E38: =0.0167*(A38)+0.2333 -> 0.417
A39: 12 | B39: 2029 | C39: 0.4863 | E39: =0.0167*(A39)+0.2333 -> 0.4337
A40: 13 | B40: 2030 | C40: 0.511 | E40: =0.0167*(A40)+0.2333 -> 0.4504

Sheet Anexo 1 Cuadro A1.9
A1: PP 139
A2: CUADRO A1.9. CAPACIDAD INSTALADA INTERCONECTADA A LA RED (MW) DE LA CFE Y DEL RESTO DE LOS PERMISIONARIOS AL 31 DE DICIEMBRE DE 20221/, EXCLUYE CENTRALES EN PRUEBAS
A4: TECNOLOGIA | B4: CFE | C4: CFE-PIE | D4: PRIVADO | E4: PEMEX | F4: TOTAL | H4: TECNOLOGIA | I4: CFE | J4: CFE-PIE | K4: PRIVADO | L4: PEMEX | M4: TOTAL
A5: Hidroeléctrica | B5: 12125 | D5: 488 | F5: 12613 | H5: Hidroeléctrica | I5: 12125 | K5: 488 | M5: 12613
A6: Geotermoeléctrica | B6: 951 | D6: 25 | F6: 976 | H6: Geotermoeléctrica | I6: 951 | K6: 25 | M6: 976
A7: Eoloeléctrica | B7: 86 | C7: 613 | D7: 6223 | F7: 6921 | H7: Eoloeléctrica | I7: 86 | J7: 613 | K7: 6223 | M7: 6921
A8: Fotovoltaica | B8: 6 | D8: 6509 | F8: 6515 | H8: Fotovoltaica | I8: 6 | K8: 6509 | M8: 6515
A9: Bioenergía | D9: 408 | F9: 408 | H9: Bioenergía | K9: 408 | M9: 408
A10: Híbrido FV-Batería | D10: 20 | F10: 20 | H10: Híbrido FV-Batería | K10: 20 | M10: 20
A11: Suma limpia renovable | B11: 13168 | C11: 613 | D11: 13673 | E11: 0 | F11: 27453 | H11: Suma limpia renovable | I11: =SUM(I5:I10) -> 13168 | J11: =SUM(J5:J10) -> 613 | K11: =SUM(K5:K10) -> 13673 | L11: =SUM(L5:L10) -> 0 | M11: =SUM(M5:M10) -> 27453
A12: Nucleoeléctrica | B12: 1608 | F12: 1608 | H12: Nucleoeléctrica | I12: 1608 | M12: 1608
A13: Cogeneracion Eficiente | D13: 1940 | E13: 367 | F13: 2308 | H13: Cogeneracion Eficiente | K13: 1940 | L13: 367 | M13: 2308
A14: Suma limpia no renovable | B14: 1608 | C14: 0 | D14: 1940 | E14: 367 | F14: 3916 | H14: Suma limpia no renovable | I14: =SUM(I12:I13) -> 1608 | J14: =SUM(J12:J13) -> 0 | K14: =SUM(K12:K13) -> 1940 | L14: =SUM(L12:L13) -> 367 | M14: =SUM(M12:M13) -> 3916
A15: Capacidad total de Energía Limpia | B15: 14776 | C15: 613 | D15: 15613 | E15: 367 | F15: 31369 | H15: Capacidad total de Energía Limpia | I15: =SUM(I11,I14) -> 14776 | J15: =SUM(J11,J14) -> 613 | K15: =SUM(K11,K14) -> 15613 | L15: =SUM(L11,L14) -> 367 | M15: =SUM(M11,M14) -> 31369
A16: Porcentaje | B16: 33.18 | C16: 3.85 | D16: 60.57 | E16: 39.9 | F16: 36 | H16: Porcentaje | I16: 33.18 | J16: 3.85 | K16: 60.57 | L16: 39.9 | M16: 36 | O16: Capacidad de CC acreditada (posible)
A17: Ciclo Combinado | B17: 11108 | C17: 15285 | D17: 8019 | F17: 34413 | H17: Ciclo Combinado | I17: 11108 | J17: 15285 | K17: 8019 | M17: 34413 | O17: =K17-'Anexo 1 A1.9.9'!B18 -> 5899
A18: Térmica Convencional | B18: 9998 | D18: 923 | E18: 422 | F18: 11343 | H18: Térmica Convencional | I18: 9998 | K18: 923 | L18: 422 | M18: 11343
A19: Turbogas | B19: 2833 | D19: 850 | E19: 131 | F19: 3815 | H19: Turbogas | I19: 2833 | K19: 850 | L19: 131 | M19: 3815
A20: Combustión Interna | B20: 355 | D20: 373 | F20: 728 | H20: Combustión Interna | I20: 355 | K20: 373 | M20: 728
A21: Carboeléctrica | B21: 5463 | F21: 5463 | H21: Carboeléctrica | I21: 5463 | M21: 5463
A22: TOTAL | B22: 44533 | C22: 15898 | D22: 25778 | E22: 921 | F22: 87130 | H22: TOTAL | I22: =SUM(I17:I21,I15) -> 44533 | J22: =SUM(J17:J21,J15) -> 15898 | K22: =SUM(K17:K21,K15) -> 25778 | L22: =SUM(L17:L21,L15) -> 920 | M22: =SUM(M17:M21,M15) -> 87131

Sheet Anexo 1 A1.9.9
A1: PP 146
A2: CUADRO A1.9.9. CAPACIDAD INSTALADA INTERCONECTADA A LA RED POR MODALIDAD Y TIPO DE TECNOLOGÍA DEL SISTEMA ELÉCTRICO NACIONAL (MW), AL 31 DE DICIEMBRE DE 20221/, EXCLUYE CENTRALES EN PRUEBAS
A5: TECNOLOGIA | B5: AUTOABASTECIMIENTO | C5: COGENERACION | D5: GENERACION | E5: GENERACION CFE | F5: PEQUEÑA PRODUCCION | G5: PRODUCCION INDEPENDIENTE | H5: USOS PROPIOS CONTINUOS | I5: TOTAL
A6: Hidroeléctrica | B6: 196 | D6: 278 | E6: 12125 | F6: 14 | I6: =SUM(B6:H6) -> 12613
A7: Geotermoeléctrica | B7: 25 | D7: 0 | E7: 951 | I7: =SUM(B7:H7) -> 976
A8: Eoloeléctrica | B8: 4172 | D8: 2048 | E8: 86 | F8: 2 | G8: 613 | I8: =SUM(B8:H8) -> 6921
A9: Fotovoltaica | B9: 497 | D9: 5912 | E9: 6 | F9: 100 | I9: =SUM(B9:H9) -> 6515
A10: Bioenergía | B10: 41 | C10: 194 | D10: 84 | H10: 89 | I10: =SUM(B10:H10) -> 408
A11: Híbrido FV-Bateria | D11: 20 | I11: =SUM(B11:H11) -> 20
A12: Suma limpia renovable | B12: =SUM(B6:B11) -> 4931 | C12: =SUM(C6:C11) -> 194 | D12: =SUM(D6:D11) -> 8342 | E12: =SUM(E6:E11) -> 13168 | F12: =SUM(F6:F11) -> 116 | G12: =SUM(G6:G11) -> 613 | H12: =SUM(H6:H11) -> 89 | I12: =SUM(B12:H12) -> 27453
A13: Nucleoeléctrica | E13: 1608 | I13: =SUM(B13:H13) -> 1608
A14: Cogeneracion Eficiente | C14: 1915 | D14: 393 | I14: =SUM(B14:H14) -> 2308
A15: Suma limpia no renovable | B15: =SUM(B13:B14) -> 0 | C15: =SUM(C13:C14) -> 1915 | D15: =SUM(D13:D14) -> 393 | E15: =SUM(E13:E14) -> 1608 | F15: =SUM(F13:F14) -> 0 | G15: =SUM(G13:G14) -> 0 | H15: =SUM(H13:H14) -> 0 | I15: =SUM(B15:H15) -> 3916
A16: Total energía limpia | B16: =SUM(B15,B12) -> 4931 | C16: =SUM(C15,C12) -> 2109 | D16: =SUM(D15,D12) -> 8735 | E16: =SUM(E15,E12) -> 14776 | F16: =SUM(F15,F12) -> 116 | G16: =SUM(G15,G12) -> 613 | H16: =SUM(H15,H12) -> 89 | I16: =SUM(B16:H16) -> 31369
A17: Porcentaje | B17: 62.98 | C17: 81.78 | D17: 54.31 | E17: 33.18 | F17: 100 | G17: 3.85 | H17: 100 | I17: =SUM(B17:H17) -> 436.1
A18: Ciclo Combinado | B18: 2120 | C18: 152 | D18: 5748 | E18: 11108 | G18: 15285 | I18: =SUM(B18:H18) -> 34413
A19: Térmica Convencional | B19: 600 | C19: 130 | D19: 615 | E19: 9998 | I19: =SUM(B19:H19) -> 11343
A20: Turbogás | B20: 31 | C20: 147 | D20: 803 | E20: 2833 | I20: =SUM(B20:H20) -> 3814
A21: Combustión Interna | B21: 148 | C21: 41 | D21: 184 | E21: 355 | I21: =SUM(B21:H21) -> 728
A22: Carboeléctrica | E22: 5463 | I22: =SUM(B22:H22) -> 5463
A23: TOTAL | B23: =SUM(B18:B22,B16) -> 7830 | C23: =SUM(C18:C22,C16) -> 2579 | D23: =SUM(D18:D22,D16) -> 16085 | E23: =SUM(E18:E22,E16) -> 44533 | F23: =SUM(F18:F22,F16) -> 116 | G23: =SUM(G18:G22,G16) -> 15898 | H23: =SUM(H18:H22,H16) -> 89 | I23: =SUM(B23:H23) -> 87130

Sheet Anexo 1 A1.12
A1: PP 152
A2: CUADRO A1.12 EVOLUCIÓN DE LA ENERGÍA NETA PRODUCIDA (GWh) 2018 - 2022 INYECTADA A LA RED POR TECNOLOGÍA, CONSIDERANDO EL FACTOR DE ACREDITACIÓN DE ENERGÍA LIMPIA A LAS CENTRALES ELÉCTRICAS CON ACREDITACIÓN COMO COGENERADOR EFICIENTE, MÁS LAS CENTRALES ELÉCTRICAS CON CEL
A3: TECNOLOGIA / FUENTE DE ENERGÍA | B3: 2018 | C3: 2019 | D3: 2020 | E3: 2021 | F3: 2022
A4: Hidroeléctrica | B4: 32234 | C4: 23602 | D4: 26817 | E4: 34717 | F4: 35561
A5: Geotermoeléctrica | B5: 5065 | C5: 5061 | D5: 4575 | E5: 4243 | F5: 4412
A6: Eoloeléctrica | B6: 12435 | C6: 16727 | D6: 19703 | E6: 21075 | F6: 20314 | H6: *Hacer back testing para ajuste
A7: Fotovoltaica | B7: 2176 | C7: 8394 | D7: 13528 | E7: 17069 | F7: 16278
A8: Bioenergía | B8: 600 | C8: 669 | D8: 600 | E8: 582 | F8: 617
A9: Híbrido FV- Batería | F9: 12
A10: Suma limpia renovable | B10: =SUM(B4:B9) -> 52510 | C10: =SUM(C4:C9) -> 54453 | D10: =SUM(D4:D9) -> 65223 | E10: =SUM(E4:E9) -> 77686 | F10: =SUM(F4:F9) -> 77194
A11: Nucleoeléctrica | B11: 13200 | C11: 10881 | D11: 10864 | E11: 11606 | F11: 10539
A12: Cogeneracion eficiente | B12: 2310 | C12: 3259 | D12: 4188 | E12: 3349 | F12: 1376
A13: Suma limpia no renovable | B13: =SUM(B11:B12) -> 15510 | C13: =SUM(C11:C12) -> 14140 | D13: =SUM(D11:D12) -> 15052 | E13: =SUM(E11:E12) -> 14955 | F13: =SUM(F11:F12) -> 11915
A14: Total energía limpia | B14: =SUM(B13,B10) -> 68020 | C14: =SUM(C13,C10) -> 68593 | D14: =SUM(D13,D10) -> 80275 | E14: =SUM(E13,E10) -> 92641 | F14: =SUM(F13,F10) -> 89109
A15: Porcentaje | B15: 21.89 | C15: 21.58 | D15: 25.7 | E15: 28.63 | F15: 26.68
A16: Ciclo Combinado | B16: 163877 | C16: 175506 | D16: 185638 | E16: 186715 | F16: 198355
A17: Térmica Convencional | B17: 39345 | C17: 38020 | D17: 22405 | E17: 22196 | F17: 20001
A18: Turbogás | B18: 9508 | C18: 10904 | D18: 8664 | E18: 11150 | F18: 10471
A19: Combustión Interna | B19: 2589 | C19: 3187 | D19: 2841 | E19: 2121 | F19: 1834
A20: Carboeléctrica | B20: 27347 | C20: 21611 | D20: 12525 | E20: 8704 | F20: 14194
A21: TOTAL | B21: =SUM(B16:B20,B14) -> 310686 | C21: =SUM(C16:C20,C14) -> 317821 | D21: =SUM(D16:D20,D14) -> 312348 | E21: =SUM(E16:E20,E14) -> 323527 | F21: =SUM(F16:F20,F14) -> 333964

Sheet Anexo 1 A1.14
A1: PP 154
A2: CUADRO A1.14 GENERACIÓN NETA EN OPERACIÓN COMERCIAL Y PRUEBAS INYECTADA A LA RED ENE-DIC 2022, SEN, POR TECNOLOGÍA Y MODALIDAD (GWh)
A3: TECNOLOGIA | B3: AUTOABASTECIMIENTO | C3: COGENERACION | D3: GENERACION | E3: GENERACION CFE | F3: PEQUEÑA PRODUCCION | G3: PRODUCCION INDEPENDIENTE | H3: USOS PROPIOS CONTINUOS | I3: TOTAL
A4: Hidroeléctrica | B4: 817 | D4: 821 | E4: 33876 | F4: 47 | I4: =SUM(B4:H4) -> 35561
A5: Geotermoeléctrica | B5: 104 | D5: 0 | E5: 4308 | I5: =SUM(B5:H5) -> 4412
A6: Eoloeléctrica | B6: 12403 | D6: 6087 | E6: 70 | F6: 0 | G6: 1753 | I6: =SUM(B6:H6) -> 20313
A7: Fotovoltaica | B7: 1358 | D7: 14653 | E7: 7 | F7: 259 | I7: =SUM(B7:H7) -> 16277
A8: Bioenergía | B8: 62 | C8: 421 | D8: 69 | H8: 66 | I8: =SUM(B8:H8) -> 618
A9: Híbrido FV-Bateria | D9: 12 | I9: =SUM(B9:H9) -> 12
A10: Suma limpia renovable | B10: =SUM(B4:B9) -> 14744 | C10: =SUM(C4:C9) -> 421 | D10: =SUM(D4:D9) -> 21642 | E10: =SUM(E4:E9) -> 38261 | F10: =SUM(F4:F9) -> 306 | G10: =SUM(G4:G9) -> 1753 | H10: =SUM(H4:H9) -> 66 | I10: =SUM(I4:I9) -> 77193
A11: Nucleoeléctrica | E11: 10539 | I11: =SUM(B11:H11) -> 10539
A12: Cogeneración Eficiente | C12: 1180 | D12: 197 | I12: =SUM(B12:H12) -> 1377
A13: Suma limpia no renovable | B13: =SUM(B11:B12) -> 0 | C13: =SUM(C11:C12) -> 1180 | D13: =SUM(D11:D12) -> 197 | E13: =SUM(E11:E12) -> 10539 | F13: =SUM(F11:F12) -> 0 | G13: =SUM(G11:G12) -> 0 | H13: =SUM(H11:H12) -> 0 | I13: =SUM(I11:I12) -> 11916
A14: Total energía limpia | B14: =SUM(B13,B10) -> 14744 | C14: =SUM(C13,C10) -> 1601 | D14: =SUM(D13,D10) -> 21839 | E14: =SUM(E13,E10) -> 48800 | F14: =SUM(F13,F10) -> 306 | G14: =SUM(G13,G10) -> 1753 | H14: =SUM(H13,H10) -> 66 | I14: =SUM(I13,I10) -> 89109
A15: Porcentaje | B15: 46.26 | C15: 13.26 | D15: 39.33 | E15: 35.58 | F15: 100 | G15: 1.81 | H15: 100 | I15: 26.68
A16: Ciclo Combinado | B16: 13646 | C16: 7836 | D16: 32367 | E16: 49300 | G16: 95206 | I16: 198355
A17: Térmica Convencional | B17: 3473 | C17: 12 | D17: 4 | E17: 16511 | I17: 20001
A18: Turbogás | B18: 2 | C18: 2262 | D18: 949 | E18: 7258 | I18: 10471
A19: Comibustión Interna | B19: 4 | C19: 353 | D19: 365 | E19: 1112 | I19: 1834
A20: Carboeléctrica | E20: 14194
A21: TOTAL | B21: =SUM(B16:B20,B14) -> 31869 | C21: =SUM(C16:C20,C14) -> 12064 | D21: =SUM(D16:D20,D14) -> 55524 | E21: =SUM(E16:E20,E14) -> 137175 | F21: =SUM(F16:F20,F14) -> 306 | G21: =SUM(G16:G20,G14) -> 96959 | H21: =SUM(H16:H20,H14) -> 66 | I21: =SUM(B21:H21) -> 333963

Sheet Anexo 3 A3.1
A1: PP 203
A2: CUADRO A3.1 METAS DE ENERGÍAS LIMPIAS E INSTRUMENTOS QUE MANDATAN
A6: AÑO | B6: METAS DE PARTICIPACIÓN DE ENERGÍAS LIMPIAS | C6: LEY O INSTRUMENTO DE PLANEACIÓN
A7: 2019 | B7: 0.25 | C7: LTE
A8: 2021 | B8: 0.3 | C8: LTE | G8: A partir de nueva gen
A9: 2024 | B9: 0.35 | C9: LTE / LGCC

Sheet Anexo 3 A3.11
A1: PP 205
A2: FIGURA A3.1 GENERACIÓN TOTAL Y PORCENTAJE DE GENERACIÓN ELÉCTRICA LIMPIA Y CONVENCIONAL 2018-2022 (GWh)
A4: AÑO | B4: GENERACIÓN TOTAL NETA GWh | C4: % CONVENCIONALES FOSILES | D4: % LIMPIAS | E4: GENERACION CONVENCIONALES | F4: GENERACION LIMPIAS | G4: COMPROBACION | I4: * Back testing
A5: 2018 | B5: 313978.24 | C5: 0.775 | D5: =1-C5 -> 0.225 | E5: =C5*B5 -> 243333.14 | F5: =D5*B5 -> 70645.104 | G5: =SUM(E5:F5) -> 313978.24
A6: 2019 | B6: 321584.42 | C6: 0.778 | D6: =1-C6 -> 0.222 | E6: =C6*B6 -> 250192.68 | F6: =D6*B6 -> 71391.741 | G6: =SUM(E6:F6) -> 321584.42
A7: 2020 | B7: 317268.51 | C7: 0.734 | D7: =1-C7 -> 0.266 | E7: =C7*B7 -> 232875.09 | F7: =D7*B7 -> 84393.424 | G7: =SUM(E7:F7) -> 317268.51
A8: 2021 | B8: 328597.97 | C8: 0.705 | D8: =1-C8 -> 0.295 | E8: =C8*B8 -> 231661.57 | F8: =D8*B8 -> 96936.401 | G8: =SUM(E8:F8) -> 328597.97
A9: 2022 | C9: 0.688 | D9: =1-C9 -> 0.312 | E9: =C9*B9 -> 0 | F9: =D9*B9 -> 0 | G9: =SUM(E9:F9) -> 0

Sheet Anexo 3 A3.2
A1: PP 207
A2: FIGURA A3.2 EVOLUCIÓN DE LA GENERACIÓN RENOVABLE TOTAL 2018-2022 (%)
A4: TECNOLOGIA | B4: 2018 | C4: 2019 | D4: 2020 | E4: 2021 | F4: 2022
A5: Hidroelectrica | B5: 32234.1 | C5: 23602.4 | D5: 26817 | E5: 34717.2 | F5: 35558.9
A6: Geotermoelectrica | B6: 5064.7 | C6: 5060.7 | D6: 4574.6 | E6: 4242.9 | F6: 4412.7
A7: Eoleoeléctrica | B7: 12435.3 | C7: 16726.9 | D7: 19702.9 | E7: 21074.9 | F7: 20528.8
A8: Fotovoltaica | B8: 3211.7 | C8: 9964.3 | D8: 15835.6 | E8: 20194.9 | F8: 20342
A9: Bioenergia | B9: 1989.2 | C9: 1866.5 | D9: 2206.5 | E9: 1595.6 | F9: 2141.3
A10: RENOVABLES TOTAL | B10: =SUM(B5:B9) -> 54935 | C10: =SUM(C5:C9) -> 57220.8 | D10: =SUM(D5:D9) -> 69136.6 | E10: =SUM(E5:E9) -> 81825.5 | F10: =SUM(F5:F9) -> 82983.7
H12: 2022 vs 2021
A13: Hidroelectrica | B13: =B5/$B$10 -> 0.586768 | C13: =C5/$C$10 -> 0.41247938 | D13: =D5/$D$10 -> 0.38788428 | E13: =E5/$E$10 -> 0.42428338 | F13: =F5/$F$10 -> 0.42850463 | H13: =F13-E13 -> 0.0042212505 | K13: *Back testing
A14: Geotermoelectrica | B14: =B6/$B$10 -> 0.092194412 | C14: =C6/$C$10 -> 0.088441616 | D14: =D6/$D$10 -> 0.066167558 | E14: =E6/$E$10 -> 0.051853029 | F14: =F6/$F$10 -> 0.053175503 | H14: =F14-E14 -> 0.0013224744
A15: Eoleoeléctrica | B15: =B7/$B$10 -> 0.22636388 | C15: =C7/$C$10 -> 0.29232202 | D15: =D7/$D$10 -> 0.28498509 | E15: =E7/$E$10 -> 0.25755907 | F15: =F7/$F$10 -> 0.24738352 | H15: =F15-E15 -> -0.010175552
A16: Fotovoltaica | B16: =B8/$B$10 -> 0.058463639 | C16: =C8/$C$10 -> 0.17413773 | D16: =D8/$D$10 -> 0.229048 | E16: =E8/$E$10 -> 0.24680448 | F16: =F8/$F$10 -> 0.24513248 | H16: =F16-E16 -> -0.0016720024
A17: Bioenergia | B17: =B9/$B$10 -> 0.036210066 | C17: =C9/$C$10 -> 0.032619257 | D17: =D9/$D$10 -> 0.031915078 | E17: =E9/$E$10 -> 0.019500034 | F17: =F9/$F$10 -> 0.025803863 | H17: =F17-E17 -> 0.0063038291
A18: COMPROBACIÓN | B18: =SUM(B13:B17) -> 1 | C18: =SUM(C13:C17) -> 1 | D18: =SUM(D13:D17) -> 1 | E18: =SUM(E13:E17) -> 1 | F18: =SUM(F13:F17) -> 1

Sheet DOF
B1: (IGNORA ESTA TAB)
A2: 44993 | B2: Comision Nacional Forestal | C2: Costos de referencia compensación ambiental por uso de suelos | D2: ACUERDO mediante el cual se expiden los costos de referencia para la compensación ambiental por cambio de uso de suelo en terrenos forestales y la metodología para su estimación | E2: https://www.dof.gob.mx/nota_detalle.php?codigo=5682057&fecha=08/03/2023#gsc.tab=0 | F2: =_xlfn.CONCAT(B2," publica ",C2) -> Comision Nacional Forestal publica Costos de referencia compensación ambiental por uso de suelos | G2: Comision Nacional Forestal publica Costos de referencia compensación ambiental por uso de suelos
A3: 45000 | B3: SENER | C3: Nota aclaratoria Programa Uso Sustentable de la Energía 2020-2024 | D3: NOTA aclaratoria al Programa Nacional para el Aprovechamiento Sustentable de la Energía 2020-2024, publicado el 16 de febrero de 2023 | E3: https://www.dof.gob.mx/nota_detalle.php?codigo=5682793&fecha=15/03/2023#gsc.tab=0 | F3: =_xlfn.CONCAT(B3," publica ",C3) -> SENER publica Nota aclaratoria Programa Uso Sustentable de la Energía 2020-2024 | G3: SENER publica Nota aclaratoria Programa Uso Sustentable de la Energía 2020-2024
A4: 45002 | B4: SENER | C4: Publicación del estatuto de Litio para México | D4: AVISO mediante el cual se informa de la publicación del Estatuto Orgánico de Litio para México. | E4: https://www.dof.gob.mx/nota_detalle.php?codigo=5683113&fecha=17/03/2023#gsc.tab=0 | F4: =_xlfn.CONCAT(B4," publica ",C4) -> SENER publica Publicación del estatuto de Litio para México | G4: SENER publica Publicación del estatuto de Litio para México
A5: 45002 | B5: SENER | C5: Aviso domicilio Litio para Mexico | D5: AVISO General por el que se da a conocer el domicilio del Organismo Público Descentralizado denominado Litio para México. | E5: https://www.dof.gob.mx/nota_detalle.php?codigo=5683114&fecha=17/03/2023#gsc.tab=0 | F5: =_xlfn.CONCAT(B5," publica ",C5) -> SENER publica Aviso domicilio Litio para Mexico | G5: SENER publica Aviso domicilio Litio para Mexico
A6: 45012 | B6: CRE | C6: Criterio de asignación de CELs 2020 | D6: ACUERDO Núm. A/001/2023 de la Comisión Reguladora de Energía por el que se establece el criterio para la asignación de Certificados de Energías Limpias disponibles en la cuenta de la Comisión Reguladora de Energía, correspondientes al año de obligación 2020. | E6: https://www.dof.gob.mx/nota_detalle.php?codigo=5683881&fecha=27/03/2023#gsc.tab=0 | F6: =_xlfn.CONCAT(B6," publica ",C6) -> CRE publica Criterio de asignación de CELs 2020 | G6: CRE publica Criterio de asignación de CELs 2020
A7: 45014 | B7: CRE | C7: DACGs medodología de calculo y ajuste de tarifas de operación CENACE | D7: ACUERDO Núm. A/026/2022 de la Comisión Reguladora de Energía por el que se expiden las disposiciones administrativas de carácter general que establecen la metodología para determinar el cálculo y ajuste de las tarifas reguladas para el servicio de operación del Centro Nacional de Control de Energía. | E7: https://www.dof.gob.mx/nota_detalle.php?codigo=5684184&fecha=29/03/2023#gsc.tab=0 | F7: =_xlfn.CONCAT(B7," publica ",C7) -> CRE publica DACGs medodología de calculo y ajuste de tarifas de operación CENACE | G7: CRE publica DACGs medodología de calculo y ajuste de tarifas de operación CENACE
A8: 45015 | B8: CRE | C8: DACGs medodología de calculo y ajuste de tarifas de operación SSB | D8: ACUERDO Núm. A/027/2022 de la Comisión Reguladora de Energía por el que se expiden las disposiciones administrativas de carácter general que establecen la metodología para determinar el cálculo y ajuste de las tarifas reguladas para el servicio de operación de los suministradores de servicios básicos de energía eléctrica. | E8: https://www.dof.gob.mx/nota_detalle.php?codigo=5684288&fecha=30/03/2023#gsc.tab=0 | F8: =_xlfn.CONCAT(B8," publica ",C8) -> CRE publica DACGs medodología de calculo y ajuste de tarifas de operación SSB | G8: CRE publica DACGs medodología de calculo y ajuste de tarifas de operación SSB
A9: 45016 | B9: CRE | C9: DACGs medodología de calculo y ajuste de tarifas de transmisión, servicio público | D9: ACUERDO Núm. A/044/2022 por el que la Comisión Reguladora de Energía expide las disposiciones administrativas de carácter general que establecen la metodología para determinar el cálculo y ajuste de las tarifas reguladas para el servicio público de transmisión de energía eléctrica. | E9: https://www.dof.gob.mx/nota_detalle.php?codigo=5684476&fecha=31/03/2023#gsc.tab=0 | F9: =_xlfn.CONCAT(B9," publica ",C9) -> CRE publica DACGs medodología de calculo y ajuste de tarifas de transmisión, servicio público | G9: CRE publica DACGs medodología de calculo y ajuste de tarifas de transmisión, servicio público
A10: 45019 | B10: CONAMER | C10: Listado de documentos CONAMER febrero 2023 | D10: LISTADO de documentos en revisión, dictaminados, autorizados, exentos y con opinión por parte de la Comisión Nacional de Mejora Regulatoria en el periodo comprendido entre el 1 y el 28 de febrero de 2023. | E10: https://www.dof.gob.mx/nota_detalle.php?codigo=5684595&fecha=03/04/2023#gsc.tab=0 | F10: =_xlfn.CONCAT(B10," publica ",C10) -> CONAMER publica Listado de documentos CONAMER febrero 2023 | G10: CONAMER publica Listado de documentos CONAMER febrero 2023
A11: 45019 | B11: CFE | C11: Modificación de DACGs ejecución de obras de la CFE y EPS | D11: MODIFICACIÓN de las Disposiciones Generales en materia de adquisiciones, arrendamientos, contratación de servicios y ejecución de obras de la Comisión Federal de Electricidad y sus empresas productivas subsidiarias. | E11: https://www.dof.gob.mx/nota_detalle.php?codigo=5684613&fecha=03/04/2023#gsc.tab=0 | F11: =_xlfn.CONCAT(B11," publica ",C11) -> CFE publica Modificación de DACGs ejecución de obras de la CFE y EPS | G11: CFE publica Modificación de DACGs ejecución de obras de la CFE y EPS
A12: 45029 | B12: CRE | C12: Publicación de norma especificaciones de seguridad RNT y RGD | D12: ACUERDO Núm. A/042/2022 por el que la Comisión Reguladora de Energía ordena la publicación del Proyecto de Norma Oficial Mexicana PROY-NOM-018-CRE-2022, Instalaciones eléctricas-Red Nacional de Transmisión y Redes Generales de Distribución-Especificaciones de seguridad | E12: https://www.dof.gob.mx/nota_detalle.php?codigo=5685497&fecha=13/04/2023 | F12: =_xlfn.CONCAT(B12," publica ",C12) -> CRE publica Publicación de norma especificaciones de seguridad RNT y RGD | G12: CRE publica Publicación de norma especificaciones de seguridad RNT y RGD
A13: 45043 | B13: CFE | C13: Tarifas SSB abril 2023 | D13: ACUERDO de la Comisión Reguladora de Energía por el que determina las tarifas finales del suministro básico aplicables para el periodo comprendido del 1 al 30 de abril de 2023 y su Anexo Único | E13: https://www.dof.gob.mx/nota_detalle.php?codigo=5686892&fecha=27/04/2023#gsc.tab=0 | F13: =_xlfn.CONCAT(B13," publica ",C13) -> CFE publica Tarifas SSB abril 2023 | G13: CFE publica Tarifas SSB abril 2023
A14: 45054 | B14: CONAMER | C14: Listado de documentos CONAMER marzo 2023 | F14: =_xlfn.CONCAT(B14," publica ",C14) -> CONAMER publica Listado de documentos CONAMER marzo 2023 | G14: CONAMER publica Listado de documentos CONAMER marzo 2023
A15: 45054 | B15: Secretaría de Economía | C15: Derogación de disposiciones a la ley minera | D15: DECRETO por el que se reforman, adicionan y derogan diversas disposiciones de la Ley Minera, de la Ley de Aguas Nacionales, de la Ley General del Equilibrio Ecológico y la Protección al Ambiente y de la Ley General para la Prevención y Gestión Integral de los Residuos, en materia de concesiones para minería y agua | F15: =_xlfn.CONCAT(B15," publica ",C15) -> Secretaría de Economía publica Derogación de disposiciones a la ley minera | G15: Secretaría de Economía publica Derogación de disposiciones a la ley minera
A16: 45054 | B16: CRE | C16: Criterios visitas de inspección CRE | D16: ACUERDO Núm. A/007/2023 por el que la Comisión Reguladora de Energía modifica el Acuerdo A/037/2016, por el que se expiden los criterios y la metodología para determinar las visitas de verificación o inspección que deberán llevarse a cabo y se establecen los criterios y la metodología para determinar las visitas de verificación que deberán llevarse a cabo en materia de electricidad. | E16: https://www.dof.gob.mx/nota_detalle.php?codigo=5687938&fecha=08/05/2023#gsc.tab=0 | F16: =_xlfn.CONCAT(B16," publica ",C16) -> CRE publica Criterios visitas de inspección CRE | G16: CRE publica Criterios visitas de inspección CRE
A17: 45054 | B17: CFE | C17: Tarifas SSB enero 2023 | F17: =_xlfn.CONCAT(B17," publica ",C17) -> CFE publica Tarifas SSB enero 2023 | G17: CFE publica Tarifas SSB enero 2023
A18: 45055 | B18: CRE | C18: Criterio de asignación de CELs 2021 | D18: ACUERDO Núm. A/013/2023 de la Comisión Reguladora de Energía por el que se establece el criterio para la asignación de Certificados de Energías Limpias disponibles en la cuenta de la Comisión Reguladora de Energía, correspondientes al año de obligación 2021. | E18: https://www.dof.gob.mx/nota_detalle.php?codigo=5688082&fecha=09/05/2023#gsc.tab=0 | F18: =_xlfn.CONCAT(B18," publica ",C18) -> CRE publica Criterio de asignación de CELs 2021 | G18: CRE publica Criterio de asignación de CELs 2021
A19: 45056 | B19: CFE | C19: Tarifas SSB marzo 2023 | D19: ACUERDO de la Comisión Reguladora de Energía por el que determina las tarifas finales del suministro básico aplicables para el periodo comprendido del 1 al 31 de marzo de 2023 y su Anexo Único. | E19: https://www.dof.gob.mx/nota_detalle.php?codigo=5688301&fecha=10/05/2023#gsc.tab=0 | F19: =_xlfn.CONCAT(B19," publica ",C19) -> CFE publica Tarifas SSB marzo 2023 | G19: CFE publica Tarifas SSB marzo 2023
A20: 45065 | B20: CRE | C20: Codigo de conducta CRE | D20: ACUERDO de la Comisión Reguladora de Energía por el que se emite el Código de Conducta de la Comisión Reguladora de Energía | E20: https://www.dof.gob.mx/nota_detalle.php?codigo=5689375&fecha=19/05/2023#gsc.tab=0 | F20: =_xlfn.CONCAT(B20," publica ",C20) -> CRE publica Codigo de conducta CRE | G20: CRE publica Codigo de conducta CRE
A21: 45065 | B21: CRE | C21: Modificación de reglas de funcionamiento OPE CRE | D21: RESOLUCIÓN de la Comisión Reguladora de Energía por la que se modifica la Resolución RES/194/2014, que modifica la diversa por la que se expidieron las Reglas generales para el funcionamiento de la Oficialía de Partes Electrónica de la Comisión Reguladora de Energía. | E21: https://www.dof.gob.mx/nota_detalle.php?codigo=5689376&fecha=19/05/2023#gsc.tab=0 | F21: =_xlfn.CONCAT(B21," publica ",C21) -> CRE publica Modificación de reglas de funcionamiento OPE CRE | G21: CRE publica Modificación de reglas de funcionamiento OPE CRE
A22: 45071 | B22: CONAMER | C22: Cambio de domicilio CONAMER | D22: ACUERDO por el que se da a conocer el cambio de domicilio de las oficinas de la Comisión Nacional de Mejora Regulatoria | E22: https://www.dof.gob.mx/nota_detalle.php?codigo=5689952&fecha=25/05/2023#gsc.tab=0 | F22: =_xlfn.CONCAT(B22," publica ",C22) -> CONAMER publica Cambio de domicilio CONAMER | G22: CONAMER publica Cambio de domicilio CONAMER
A23: 45072 | B23: CRE | C23: Actualización de valolres de referencia eficiencia de cogeneración y energía libre de combustible | D23: ACUERDO Núm. A/018/2023 de la Comisión Reguladora de Energía por el que se actualizan los valores de referencia de las metodologías para el cálculo de la eficiencia de los sistemas de cogeneración de energía eléctrica y los criterios para determinar la cogeneración eficiente, así como los criterios de eficiencia y metodología de cálculo para determinar el porcentaje de energía libre de combustible establecidos en las resoluciones RES/003/2011, RES/206/2014, RES/291/2012 y RES/1838/2016, respectivamente. | E23: https://www.dof.gob.mx/nota_detalle.php?codigo=5690142&fecha=26/05/2023#gsc.tab=0 | F23: =_xlfn.CONCAT(B23," publica ",C23) -> CRE publica Actualización de valolres de referencia eficiencia de cogeneración y energía libre de combustible | G23: CRE publica Actualización de valolres de referencia eficiencia de cogeneración y energía libre de combustible

Sheet 3.8 GD
D1: Evolución Capacidad Instalada Acumulada FGD | N1: Generación Acumulada Anua (GHW)
B2: n | C2: Año | D2: MW | E2: E1 planificado | F2: Pronóstico E1 | I2: E2 (Acelerado) | J2: Pronóstico E2
F3: Exponencial simple | G3: y=545.69*EXP(0.1179*X) | H3: Promedio | J3: Exponencial simple | K3: y=434.26*EXP(0.1403*X) | L3: Promedio
A4: PRODESEN 2022 | B4: 1 | C4: 2009 | D4: 0.1 | E4: 0.1 | F4: y=380*EXP(0.1179*X) | I4: 0.1
B5: 2 | C5: 2010 | D5: 0.8 | E5: 0.8 | I5: 0.8
B6: 3 | C6: 2011 | D6: 3.4 | E6: 3.4 | I6: 3.4
B7: 4 | C7: 2012 | D7: 13 | E7: 13 | I7: 13
B8: 5 | C8: 2013 | D8: 27 | E8: 27 | I8: 27
B9: 6 | C9: 2014 | D9: 58 | E9: 58 | I9: 58
B10: 7 | C10: 2015 | D10: 114 | E10: 114 | I10: 114
B11: 8 | C11: 2016 | D11: 244 | E11: 244 | I11: 244
B12: 9 | C12: 2017 | D12: 455 | E12: 455 | I12: 455
B13: 10 | C13: 2018 | D13: 689 | E13: 689 | I13: 689
B14: 11 | C14: 2019 | D14: 1076 | E14: 1076 | H14: =E14 -> 1076 | I14: 1076 | L14: =I14 -> 1076
B15: 12 | C15: 2020 | D15: 1540 | E15: 1540 | F15: =380*EXP(0.1179*B15) -> 1563.952 | G15: =545.69*EXP(0.1179*B15) -> 2245.8763 | H15: =E15 -> 1540 | I15: 1540 | J15: =290*EXP(0.1403*B15) -> 1561.623 | K15: =434.26*EXP(0.1403*B15) -> 2338.4496 | L15: =I15 -> 1540
B16: 13 | C16: 2021 | D16: 2015 | E16: 2015 | F16: =380*EXP(0.1179*B16) -> 1759.6518 | G16: =545.69*EXP(0.1179*B16) -> 2526.9064 | H16: =E16 -> 2015 | I16: 2015 | J16: =290*EXP(0.1403*B16) -> 1796.833 | K16: =434.26*EXP(0.1403*B16) -> 2690.6644 | L16: =I16 -> 2015
B17: 14 | C17: 2022 | D17: 2613 | E17: 2613 | F17: =380*EXP(0.1179*B17) -> 1979.8399 | G17: =545.69*EXP(0.1179*B17) -> 2843.1022 | H17: =E17 -> 2613 | I17: 2613 | J17: =290*EXP(0.1403*B17) -> 2067.47 | K17: =434.26*EXP(0.1403*B17) -> 3095.9294 | L17: =I17 -> 2613
B18: 15 | C18: 2023 | E18: 3000 | F18: =380*EXP(0.1179*B18) -> 2227.5804 | G18: =545.69*EXP(0.1179*B18) -> 3198.8641 | H18: =AVERAGE(F18:G18) -> 2713.2222 | I18: 4000 | J18: =290*EXP(0.1403*B18) -> 2378.8701 | K18: =434.26*EXP(0.1403*B18) -> 3562.235 | L18: =AVERAGE(J18:K18) -> 2970.5526
B19: 16 | C19: 2024 | F19: =380*EXP(0.1179*B19) -> 2506.3211 | G19: =545.69*EXP(0.1179*B19) -> 3599.143 | H19: =AVERAGE(F19:G19) -> 3052.7321 | J19: =290*EXP(0.1403*B19) -> 2737.173 | K19: =434.26*EXP(0.1403*B19) -> 4098.775 | L19: =AVERAGE(J19:K19) -> 3417.974
B20: 17 | C20: 2025 | F20: =380*EXP(0.1179*B20) -> 2819.941 | G20: =545.69*EXP(0.1179*B20) -> 4049.5095 | H20: =AVERAGE(F20:G20) -> 3434.7253 | J20: =290*EXP(0.1403*B20) -> 3149.4431 | K20: =434.26*EXP(0.1403*B20) -> 4716.1281 | L20: =AVERAGE(J20:K20) -> 3932.7856
B21: 18 | C21: 2026 | E21: 5627 | F21: =380*EXP(0.1179*B21) -> 3172.8047 | G21: =545.69*EXP(0.1179*B21) -> 4556.2311 | H21: =E21 -> 5627 | I21: 7473 | J21: =290*EXP(0.1403*B21) -> 3623.8089 | K21: =434.26*EXP(0.1403*B21) -> 5426.4663 | L21: =I21 -> 7473
B22: 19 | C22: 2027 | F22: =380*EXP(0.1179*B22) -> 3569.8229 | G22: =545.69*EXP(0.1179*B22) -> 5126.3596 | H22: =AVERAGE(F22:G22) -> 4348.0912 | J22: =290*EXP(0.1403*B22) -> 4169.6231 | K22: =434.26*EXP(0.1403*B22) -> 6243.7949 | L22: =AVERAGE(J22:K22) -> 5206.709
B23: 20 | C23: 2028 | F23: =380*EXP(0.1179*B23) -> 4016.5205 | G23: =545.69*EXP(0.1179*B23) -> 5767.8291 | H23: =AVERAGE(F23:G23) -> 4892.1748 | J23: =290*EXP(0.1403*B23) -> 4797.6473 | K23: =434.26*EXP(0.1403*B23) -> 7184.2286 | L23: =AVERAGE(J23:K23) -> 5990.9379
B24: 21 | C24: 2029 | F24: =380*EXP(0.1179*B24) -> 4519.1141 | G24: =545.69*EXP(0.1179*B24) -> 6489.5667 | H24: =AVERAGE(F24:G24) -> 5504.3404 | J24: =290*EXP(0.1403*B24) -> 5520.2638 | K24: =434.26*EXP(0.1403*B24) -> 8266.3095 | L24: =AVERAGE(J24:K24) -> 6893.2866
